<mujoco>
	<option gravity="0 0 0.0">
		<flag contact="enable" />
	</option>
	<worldbody>

        <light diffuse=".5 .5 .5" pos="0 0 10" dir="0 0 -1"/>
		<geom type="plane" size="3 3 0.1" rgba=".9 0 0 1"/>
		<body pos="0.5 0 0.1" euler="0 90 0">
			<joint name ="joint0" type="hinge" axis="-1 0 0" pos="0 0 -0.5"/>
			<geom type="cylinder" size="0.05 0.5" rgba="0 .9 0.9 1"/>
			<body pos="0 0 1" euler="0 0 0">
				<joint name ="joint1" type="hinge" axis="-1 0 0" pos="0 0 -0.5"/>
				<geom type="cylinder" size="0.05 0.5" rgba="0 1 0 1"/>
				<site name="tip0" size="0.1" pos="0 0 0.5"/>
				<body pos="0 0 1" euler="0 0 0">
					<joint name ="joint2" type="hinge" axis="-1 0 0" pos="0 0 -0.5"/>
					<geom type="cylinder" size="0.05 0.5" rgba="1 1 0 1"/>
					<site name="tip1" size="0.1" pos="0 0 0.5"/>
				</body>
			</body>
		</body>

	</worldbody>

	<sensor>
		<framepos objtype="site" objname="tip0"/>
		<framepos objtype="site" objname="tip1"/>
	</sensor>

	<actuator>
		<motor name="torq_servo0" joint="joint0" />
		<motor name="torq_servo1" joint="joint1" />
		<motor name="torq_servo2" joint="joint2" />
	</actuator>

	<keyframe>
    	<key name="homepos" qpos="0 0 0" />
	</keyframe>

</mujoco>